<?xml version='1.0'?>

<robot name="my_droid" xmlns:xacro="http://www.ros.org/wiki/xacro">
  
  <xacro:include filename="$(find my_droid)/urdf/udacity_bot.gazebo" />

  <link name="robot_footprint"></link>

  <joint name="robot_footprint_joint" type="fixed">
    <origin xyz="0 0 0" rpy="0 0 0" />
    <parent link="robot_footprint"/>
    <child link="body" />
  </joint>
  
  <material name="blue">
    <color rgba="0 0 0.8 1"/>
    </material>
  
  <material name="black">
    <color rgba="0 0 0 1"/>
    </material>
    
  <material name="white">
    <color rgba="1 1 1 1"/>
    </material>

  <link name='body'>
    <pose>0 0 -0.25 0 0 0</pose>
    <inertial>
      <mass value="10.0"/>
      <origin xyz="0 0 0" rpy=" 0 0 0"/>
      <inertia
          ixx="0.1" ixy="0" ixz="0"
          iyy="0.1" iyz="0"
          izz="0.8"
               />
    </inertial>

    <collision name='body_collision'>
      <origin xyz="0 0 0" rpy=" 0 0 0"/> 
      <geometry>
        <cylinder length="0.5" radius="0.27"/>
      </geometry>
    </collision>

    <visual name='body_visual'>
      <origin xyz="0 0 0" rpy=" 0 0 0"/>
      <geometry>
        <cylinder length="0.5" radius="0.27"/>
      </geometry>
      <material name="blue"/>
    </visual>
    
    <collision name='back_caster_collision'>
      <origin xyz="-0.2 0 -0.249" rpy=" 0 0 0"/>
      <geometry>
        <sphere radius="0.049"/>
      </geometry>
      <surface>
        <friction>
          <ode>
            <mu>0</mu>
            <mu2>0</mu2>
            <slip1>1.0</slip1>
            <slip2>1.0</slip2>
          </ode>
        </friction>
      </surface>
    </collision>

    <visual name='back_caster_visual'>
      <origin xyz="-0.2 0 -0.249" rpy=" 0 0 0"/>
      <geometry>
        <sphere radius="0.049"/>
      </geometry>
      <material name="white"/>
    </visual>

    <collision name='front_caster_collision'>
      <origin xyz="0.2 0 -0.249" rpy=" 0 0 0"/>
      <geometry>
        <sphere radius="0.049"/>
      </geometry>
      <surface>
        <friction>
          <ode>
            <mu>0</mu>
            <mu2>0</mu2>
            <slip1>1.0</slip1>
            <slip2>1.0</slip2>
          </ode>
        </friction>
      </surface>
    </collision>

    <visual name='front_caster_visual'>
      <origin xyz="0.2 0 -0.249" rpy="0 0 0"/>
      <geometry>
        <sphere radius="0.048"/>
      </geometry>
      <material name="white"/>
    </visual>
  </link>
  
    <link name='left_wheel'>
    <inertial>
      <mass value="5.0"/>
      <origin xyz="0 0 0" rpy="0 1.5707 1.5707"/>
      <inertia
          ixx="0.1" ixy="0" ixz="0"
          iyy="0.1" iyz="0"
          izz="0.1"
      />
    </inertial>

    <visual name='left_wheel_visual'>
     <origin xyz="0 0 0" rpy=" 0 1.5707 1.5707"/>
     <geometry>
      <cylinder length="0.05" radius="0.1"/>
     </geometry>
     <material name="black"/>
    </visual>

    <collision name='left_wheel_collision'>
     <origin xyz="0 0 0" rpy=" 0 1.5707 1.5707"/>
     <geometry>
       <cylinder length="0.05" radius="0.1"/>
     </geometry>
    </collision>
  </link>

  <joint type="continuous" name="left_wheel_hinge">
    <origin xyz="0 0.32 -0.198" rpy="0 0 0"/>
    <child link="left_wheel"/>
    <parent link="body"/>
    <axis xyz="0 1 0" rpy="0 0 0"/>
    <limit effort="10000" velocity="1000"/>
    <joint_properties damping="1.0" friction="1.0"/>
  </joint>

  <link name='right_wheel'>
    <inertial>
      <mass value="5.0"/>
      <origin xyz="0 0 0" rpy="0 1.5707 1.5707"/>
      <inertia
          ixx="0.1" ixy="0" ixz="0"
          iyy="0.1" iyz="0"
          izz="0.1"
      />
    </inertial>

    <visual name='right_wheel_visual'>
     <origin xyz="0 0 0" rpy=" 0 1.5707 1.5707"/>
     <geometry>
      <cylinder length="0.05" radius="0.1"/>
     </geometry>
     <material name="black"/>
    </visual>

    <collision name='right_wheel_collision'>
     <origin xyz="0 0 0" rpy=" 0 1.5707 1.5707"/>
     <geometry>
       <cylinder length="0.05" radius="0.1"/>
     </geometry>
    </collision>
  </link>

  <joint type="continuous" name="right_wheel_hinge">
    <origin xyz="0 -0.32 -0.198" rpy="0 0 0"/>
    <child link="right_wheel"/>
    <parent link="body"/>
    <axis xyz="0 1 0" rpy="0 0 0"/>
    <limit effort="10000" velocity="1000"/>
    <joint_properties damping="1.0" friction="1.0"/>
  </joint>
  
  <link name='head'>
    <inertial>
      <mass value="5.0"/>
      <origin xyz="0 0 0" rpy="0 0 0"/>
      <inertia
          ixx="1.0" ixy="0" ixz="0"
          iyy="1.0" iyz="0"
          izz="1.0"
               />
      </inertial>
      
      <collision name="head">
        <origin xyz="0 0 0" rpy="0 0 0"/>
        <geometry>
          <sphere radius="0.2"/>
        </geometry>
      </collision>
      
     <visual name='head_visual'>
     <origin xyz="0 0 0" rpy=" 0 0 0"/>
     <geometry>
          <sphere radius="0.2"/>
     </geometry>
     <material name="black"/>
    </visual>
   </link>
    
  <joint type="fixed" name="head_hinge">
    <origin xyz="0 0 0.45" rpy="0 0 0"/>
    <child link="head"/>
    <parent link="body"/>
    <axis xyz="0 0 1" rpy="0 0 0"/>
  </joint>
    
  <link name='camera'>
    <inertial>
      <mass value="0.1"/>
      <origin xyz="0 0 0" rpy="0 0 0"/>
      <inertia
          ixx="1e-6" ixy="0" ixz="0"
          iyy="1e-6" iyz="0"
          izz="1e-6"
      />
    </inertial>

    <visual name='camera_visual'>
     <origin xyz="0 0 0" rpy=" 0 0 0"/>
     <geometry>
      <box size="0.05 0.05 0.05"/>
     </geometry>
    </visual>

    <collision name='camera_collision'>
     <origin xyz="0 0 0" rpy=" 0 0 0"/>
     <geometry>
      <box size="0.05 0.05 0.05"/>
     </geometry>
    </collision>
    
  </link>

  <joint type="fixed" name="camera_joint">
    <origin xyz="0.2 0 0" rpy="0 0 0"/>
    <child link="camera"/>
    <parent link="head"/>
    <axis xyz="1 0 0" rpy="0 0 0"/>
  </joint>

  <link name='Hokuyo_base'>
    <inertial>
      <mass value="0.1"/>
      <origin xyz="0 0 0" rpy="0 0 0"/>
      <inertia
          ixx="1e-6" ixy="0" ixz="0"
          iyy="1e-6" iyz="0"
          izz="1e-6"
      />
    </inertial>

    <visual name='base_visual'>
     <origin xyz="0 0 0" rpy=" 0 0 0"/>
     <geometry>
      <box size="0.1 0.1 0.1"/>
     </geometry>
     <material name="blue"/>
    </visual>

    <collision name='hokuyo_collision'>
     <origin xyz="0 0 0" rpy=" 0 0 0"/>
     <geometry>
      <box size="0.1 0.1 0.1"/>
     </geometry>
    </collision>
   </link>
 
   <joint type="fixed" name="Base_joint">
    <origin xyz="0.32 0 -0.20" rpy="0 0 0"/>
    <child link="Hokuyo_base"/>
    <parent link="body"/>
    <axis xyz="1 0 0" rpy="0 0 0"/>
  </joint>
      
  <link name='hokuyo'>
    <inertial>
      <mass value="0.1"/>
      <origin xyz="0 0 0" rpy="0 0 0"/>
      <inertia
          ixx="1e-6" ixy="0" ixz="0"
          iyy="1e-6" iyz="0"
          izz="1e-6"
      />
    </inertial>

    <visual name='hokuyo_visual'>
     <origin xyz="0 0 0" rpy=" 0 0 0"/>
     <geometry>
      <mesh filename="package://my_droid/meshes/hokuyo.dae"/>
     </geometry>
    </visual>

    <collision name='hokuyo_collision'>
     <origin xyz="0 0 0" rpy=" 0 0 0"/>
     <geometry>
      <box size="0.1 0.1 0.1"/>
     </geometry>
    </collision> 
  </link>

  <joint type="fixed" name="hokuyo_joint">
    <origin xyz="0 0 0.1" rpy="0 0 0"/>
    <child link="hokuyo"/>
    <parent link="Hokuyo_base"/>
    <axis xyz="0 0 1" rpy="0 0 0"/>
  </joint>

</robot>
